#usda 1.0
(
    customLayerData = {
        string creator = "URDF USD Converter v0.1.3"
    }
    defaultPrim = "Aloha"
    doc = """Generated from Composed Stage of root layer /tmp/tmpp4lo4na3/Aloha.usdc


Generated from Composed Stage of root layer /tmp/urdf_import_Aloha_bhz_ku6h/usdex_Aloha/Aloha.usdc


Generated from Composed Stage of root layer /tmp/urdf_import_Aloha_bhz_ku6h/temp_Aloha/Aloha.usd


Generated from Composed Stage of root layer /home/gtu_dsa/dash-aloha-mini-isaacsim/assets/usd/Aloha/payloads/base.usd
"""
    kilogramsPerUnit = 1
    metersPerUnit = 1
    upAxis = "Z"
)

over "Aloha"
{
    over "Geometry"
    {
        over "base_link" (
            prepend apiSchemas = ["PhysicsRigidBodyAPI", "PhysicsArticulationRootAPI", "NewtonArticulationRootAPI", "PhysicsMassAPI"]
        )
        {
            bool newton:selfCollisionEnabled = 0
            point3f physics:centerOfMass = (-0.0008464791, 0.009789168, 0.34475332)
            float3 physics:diagonalInertia = (0.020065764, 0.02139627, 0.022120548)
            float physics:mass = 5.098021
            quatf physics:principalAxes = (0.053774793, 0.72879505, 0.68230623, 0.020598525)

            over "wheel1" (
                prepend apiSchemas = ["PhysicsRigidBodyAPI", "PhysicsMassAPI"]
            )
            {
                point3f physics:centerOfMass = (-0.000052748797, 0.015774114, -1.8443045e-7)
                float3 physics:diagonalInertia = (0.000050889208, 0.000050890223, 0.00009363524)
                float physics:mass = 0.19481896
                quatf physics:principalAxes = (0.7070448, -0.70704466, -0.0093680015, 0.009368598)
            }

            over "wheel2" (
                prepend apiSchemas = ["PhysicsRigidBodyAPI", "PhysicsMassAPI"]
            )
            {
                point3f physics:centerOfMass = (-0.000006449473, 0.015774066, -0.00005235616)
                float3 physics:diagonalInertia = (0.000050889004, 0.000050890045, 0.000093635)
                float physics:mass = 0.19481803
                quatf physics:principalAxes = (0.54758054, 0.5475798, 0.4473876, 0.44738817)
            }

            over "wheel3" (
                prepend apiSchemas = ["PhysicsRigidBodyAPI", "PhysicsMassAPI"]
            )
            {
                point3f physics:centerOfMass = (0.0002175891, 0.015772652, -0.0000456401)
                float3 physics:diagonalInertia = (0.00005088899, 0.00005089051, 0.00009363505)
                float physics:mass = 0.19481853
                quatf physics:principalAxes = (0.6627051, -0.65880907, 0.25684896, -0.24661948)
            }

            over "vertical_link" (
                prepend apiSchemas = ["PhysicsRigidBodyAPI", "PhysicsMassAPI"]
            )
            {
                point3f physics:centerOfMass = (-0.00018840606, 0.008855787, 0.6535164)
                float3 physics:diagonalInertia = (0.0037507834, 0.0125141265, 0.015564449)
                float physics:mass = 1.5296998
                quatf physics:principalAxes = (0.7270734, -0.6865346, 0.0038845832, 0.0044171154)

                over "left_link1" (
                    prepend apiSchemas = ["PhysicsRigidBodyAPI", "PhysicsMassAPI"]
                )
                {
                    point3f physics:centerOfMass = (0.00012110697, -0.031318713, 0.0119674)
                    float3 physics:diagonalInertia = (0.00002937687, 0.000056470984, 0.000059862527)
                    float physics:mass = 0.124705
                    quatf physics:principalAxes = (0.6982905, -0.07532554, 0.70995706, 0.051743567)

                    over "left_link2" (
                        prepend apiSchemas = ["PhysicsRigidBodyAPI", "PhysicsMassAPI"]
                    )
                    {
                        point3f physics:centerOfMass = (0.019956874, 0.07428563, 0.004221139)
                        float3 physics:diagonalInertia = (0.000057629386, 0.00015179618, 0.00018690171)
                        float physics:mass = 0.15999518
                        quatf physics:principalAxes = (-0.00075268914, 0.7029946, 0.7111869, -0.0033544488)

                        over "left_link3" (
                            prepend apiSchemas = ["PhysicsRigidBodyAPI", "PhysicsMassAPI"]
                        )
                        {
                            point3f physics:centerOfMass = (0.018863553, -0.076481834, 0.0007403652)
                            float3 physics:diagonalInertia = (0.000039621544, 0.00009796036, 0.0001253882)
                            float physics:mass = 0.13554297
                            quatf physics:principalAxes = (0.007414604, 0.7026511, 0.7113736, 0.0131939305)

                            over "left_link4" (
                                prepend apiSchemas = ["PhysicsRigidBodyAPI", "PhysicsMassAPI"]
                            )
                            {
                                point3f physics:centerOfMass = (0.02798382, -0.036306825, 0.00038482904)
                                float3 physics:diagonalInertia = (0.000016215097, 0.000024853514, 0.000031436357)
                                float physics:mass = 0.07428787
                                quatf physics:principalAxes = (0.9928963, 0.0015699025, 0.008526183, 0.11866637)

                                over "left_link5" (
                                    prepend apiSchemas = ["PhysicsRigidBodyAPI", "PhysicsMassAPI"]
                                )
                                {
                                    point3f physics:centerOfMass = (0.00008083938, -0.026340941, -0.0056023696)
                                    float3 physics:diagonalInertia = (0.000023958666, 0.000042315143, 0.000049263)
                                    float physics:mass = 0.09920476
                                    quatf physics:principalAxes = (-0.37258852, 0.6076591, 0.39063922, 0.5825197)

                                    over "left_link6" (
                                        prepend apiSchemas = ["PhysicsRigidBodyAPI", "PhysicsMassAPI"]
                                    )
                                    {
                                        point3f physics:centerOfMass = (-0.020403894, -0.0015975804, 0.02974645)
                                        float3 physics:diagonalInertia = (0.000003239614, 0.000009143836, 0.00001148181)
                                        float physics:mass = 0.020845411
                                        quatf physics:principalAxes = (0.5225519, 0.48799902, 0.47202837, 0.515738)
                                    }
                                }
                            }
                        }
                    }
                }

                over "right_link1" (
                    prepend apiSchemas = ["PhysicsRigidBodyAPI", "PhysicsMassAPI"]
                )
                {
                    point3f physics:centerOfMass = (0.00012110697, -0.031318713, 0.0119674)
                    float3 physics:diagonalInertia = (0.00002937687, 0.000056470984, 0.000059862527)
                    float physics:mass = 0.124705
                    quatf physics:principalAxes = (0.6982905, -0.07532554, 0.70995706, 0.051743567)

                    over "right_link2" (
                        prepend apiSchemas = ["PhysicsRigidBodyAPI", "PhysicsMassAPI"]
                    )
                    {
                        point3f physics:centerOfMass = (0.019956874, 0.07428563, 0.004221139)
                        float3 physics:diagonalInertia = (0.000057629386, 0.00015179618, 0.00018690171)
                        float physics:mass = 0.15999518
                        quatf physics:principalAxes = (-0.000752689, 0.7029946, 0.7111869, -0.0033544488)

                        over "right_link3" (
                            prepend apiSchemas = ["PhysicsRigidBodyAPI", "PhysicsMassAPI"]
                        )
                        {
                            point3f physics:centerOfMass = (0.018863553, -0.076481834, 0.0007403652)
                            float3 physics:diagonalInertia = (0.000039621544, 0.00009796036, 0.0001253882)
                            float physics:mass = 0.13554297
                            quatf physics:principalAxes = (0.0074146045, 0.7026511, 0.71137357, 0.01319393)

                            over "right_link4" (
                                prepend apiSchemas = ["PhysicsRigidBodyAPI", "PhysicsMassAPI"]
                            )
                            {
                                point3f physics:centerOfMass = (0.02798382, -0.036306825, 0.00038482907)
                                float3 physics:diagonalInertia = (0.000016215097, 0.000024853516, 0.000031436357)
                                float physics:mass = 0.07428787
                                quatf physics:principalAxes = (0.9928963, 0.0015699064, 0.008526183, 0.11866638)

                                over "right_link5" (
                                    prepend apiSchemas = ["PhysicsRigidBodyAPI", "PhysicsMassAPI"]
                                )
                                {
                                    point3f physics:centerOfMass = (0.00008083988, -0.026340941, -0.005602369)
                                    float3 physics:diagonalInertia = (0.000023958666, 0.000042315143, 0.000049263)
                                    float physics:mass = 0.09920476
                                    quatf physics:principalAxes = (-0.37258852, 0.6076591, 0.39063922, 0.58251977)

                                    over "right_link6" (
                                        prepend apiSchemas = ["PhysicsRigidBodyAPI", "PhysicsMassAPI"]
                                    )
                                    {
                                        point3f physics:centerOfMass = (-0.020403894, -0.0015975804, 0.02974645)
                                        float3 physics:diagonalInertia = (0.000003239614, 0.000009143836, 0.00001148181)
                                        float physics:mass = 0.020845411
                                        quatf physics:principalAxes = (0.5225519, 0.48799902, 0.47202837, 0.515738)
                                    }
                                }
                            }
                        }
                    }
                }
            }
        }
    }

    over "Physics"
    {
        def PhysicsRevoluteJoint "wheel1" (
            prepend apiSchemas = ["PhysicsDriveAPI:angular", "PhysicsJointStateAPI:angular"]
        )
        {
            uniform token physics:axis = "Y"
            custom rel physics:body0
            prepend rel physics:body0 = </Aloha/Geometry/base_link>
            custom rel physics:body1
            prepend rel physics:body1 = </Aloha/Geometry/base_link/wheel1>
            point3f physics:localPos0 = (-0.1538, 0.091161, 0.0422)
            point3f physics:localPos1 = (0, 0, 0)
            quatf physics:localRot0 = (-0, 0.49327123, -0.86987555, 0)
            quatf physics:localRot1 = (0, -1, 0, 0)
        }

        def PhysicsRevoluteJoint "wheel2" (
            prepend apiSchemas = ["PhysicsDriveAPI:angular", "PhysicsJointStateAPI:angular"]
        )
        {
            uniform token physics:axis = "Y"
            custom rel physics:body0
            prepend rel physics:body0 = </Aloha/Geometry/base_link>
            custom rel physics:body1
            prepend rel physics:body1 = </Aloha/Geometry/base_link/wheel2>
            point3f physics:localPos0 = (0.15563, 0.087993, 0.0422)
            point3f physics:localPos1 = (0, 0, 0)
            quatf physics:localRot0 = (0, -0.50363076, -0.863919, 0)
            quatf physics:localRot1 = (0, -1, 0, 0)
        }

        def PhysicsRevoluteJoint "wheel3" (
            prepend apiSchemas = ["PhysicsDriveAPI:angular", "PhysicsJointStateAPI:angular"]
        )
        {
            uniform token physics:axis = "X"
            custom rel physics:body0
            prepend rel physics:body0 = </Aloha/Geometry/base_link>
            custom rel physics:body1
            prepend rel physics:body1 = </Aloha/Geometry/base_link/wheel3>
            point3f physics:localPos0 = (-0.0020354, -0.17875, 0.0422)
            point3f physics:localPos1 = (0, 0, 0)
            quatf physics:localRot0 = (0.70161384, 0, 0, -0.7125574)
            quatf physics:localRot1 = (0.70161384, 0, 0, -0.7125574)
        }

        def PhysicsPrismaticJoint "vertical_move" (
            prepend apiSchemas = ["PhysicsDriveAPI:linear", "PhysicsJointStateAPI:linear"]
        )
        {
            float drive:linear:physics:maxForce = 200
            uniform token physics:axis = "Z"
            custom rel physics:body0
            prepend rel physics:body0 = </Aloha/Geometry/base_link>
            custom rel physics:body1
            prepend rel physics:body1 = </Aloha/Geometry/base_link/vertical_link>
            point3f physics:localPos0 = (-0.001045, -0.067891, 0.064)
            point3f physics:localPos1 = (0, 0, 0)
            quatf physics:localRot0 = (1, 0, 0, 0)
            quatf physics:localRot1 = (1, 0, 0, 0)
            float physics:lowerLimit = 0
            float physics:upperLimit = 0.6
            custom float urdf:limit:effort = 200
            custom float urdf:limit:velocity = 0.15
        }

        def PhysicsRevoluteJoint "left_joint1" (
            prepend apiSchemas = ["PhysicsDriveAPI:angular", "PhysicsJointStateAPI:angular"]
        )
        {
            float drive:angular:physics:maxForce = 30
            uniform token physics:axis = "X"
            custom rel physics:body0
            prepend rel physics:body0 = </Aloha/Geometry/base_link/vertical_link>
            custom rel physics:body1
            prepend rel physics:body1 = </Aloha/Geometry/base_link/vertical_link/left_link1>
            point3f physics:localPos0 = (0.15661682, -0.019101774, 0.75353765)
            point3f physics:localPos1 = (0, 0, 0)
            quatf physics:localRot0 = (0.7071489, 0, 0.7070294, 0.007062092)
            quatf physics:localRot1 = (0.7071489, 0, 0.7070294, 0.007062092)
            float physics:lowerLimit = -109.99988
            float physics:upperLimit = 109.99988
            custom float urdf:limit:effort = 30
            custom float urdf:limit:velocity = 3
        }

        def PhysicsRevoluteJoint "left_joint2" (
            prepend apiSchemas = ["PhysicsDriveAPI:angular", "PhysicsJointStateAPI:angular"]
        )
        {
            float drive:angular:physics:maxForce = 30
            uniform token physics:axis = "X"
            custom rel physics:body0
            prepend rel physics:body0 = </Aloha/Geometry/base_link/vertical_link/left_link1>
            custom rel physics:body1
            prepend rel physics:body1 = </Aloha/Geometry/base_link/vertical_link/left_link1/left_link2>
            point3f physics:localPos0 = (-0.01727994, -0.0311811, 0.053936154)
            point3f physics:localPos1 = (0, 0, 0)
            quatf physics:localRot0 = (0.9999987, 0, -0.000043497945, -0.0016003461)
            quatf physics:localRot1 = (0.9999987, 0, -0.000043497945, -0.0016003461)
            float physics:lowerLimit = -100.000046
            float physics:upperLimit = 100.000046
            custom float urdf:limit:effort = 30
            custom float urdf:limit:velocity = 3
        }

        def PhysicsRevoluteJoint "left_joint3" (
            prepend apiSchemas = ["PhysicsDriveAPI:angular", "PhysicsJointStateAPI:angular"]
        )
        {
            float drive:angular:physics:maxForce = 30
            uniform token physics:axis = "X"
            custom rel physics:body0
            prepend rel physics:body0 = </Aloha/Geometry/base_link/vertical_link/left_link1/left_link2>
            custom rel physics:body1
            prepend rel physics:body1 = </Aloha/Geometry/base_link/vertical_link/left_link1/left_link2/left_link3>
            point3f physics:localPos0 = (0.0028523, 0.11238, 0.028829)
            point3f physics:localPos1 = (0, 0, 0)
            quatf physics:localRot0 = (0.9999889, 0, -0.004408358, -0.0016460567)
            quatf physics:localRot1 = (0.9999889, 0, -0.004408358, -0.0016460567)
            float physics:lowerLimit = -100.000046
            float physics:upperLimit = 90.00021
            custom float urdf:limit:effort = 30
            custom float urdf:limit:velocity = 3
        }

        def PhysicsRevoluteJoint "left_joint4" (
            prepend apiSchemas = ["PhysicsDriveAPI:angular", "PhysicsJointStateAPI:angular"]
        )
        {
            float drive:angular:physics:maxForce = 30
            uniform token physics:axis = "X"
            custom rel physics:body0
            prepend rel physics:body0 = </Aloha/Geometry/base_link/vertical_link/left_link1/left_link2/left_link3>
            custom rel physics:body1
            prepend rel physics:body1 = </Aloha/Geometry/base_link/vertical_link/left_link1/left_link2/left_link3/left_link4>
            point3f physics:localPos0 = (0.0004820973, -0.13414858, 0.0036238108)
            point3f physics:localPos1 = (0, 0, 0)
            quatf physics:localRot0 = (0.9999436, 0, -0.008725049, -0.0060510905)
            quatf physics:localRot1 = (0.9999436, 0, -0.008725049, -0.0060510905)
            float physics:lowerLimit = -94.99984
            float physics:upperLimit = 94.99984
            custom float urdf:limit:effort = 30
            custom float urdf:limit:velocity = 3
        }

        def PhysicsRevoluteJoint "left_joint5" (
            prepend apiSchemas = ["PhysicsDriveAPI:angular", "PhysicsJointStateAPI:angular"]
        )
        {
            float drive:angular:physics:maxForce = 30
            uniform token physics:axis = "X"
            custom rel physics:body0
            prepend rel physics:body0 = </Aloha/Geometry/base_link/vertical_link/left_link1/left_link2/left_link3/left_link4>
            custom rel physics:body1
            prepend rel physics:body1 = </Aloha/Geometry/base_link/vertical_link/left_link1/left_link2/left_link3/left_link4/left_link5>
            point3f physics:localPos0 = (0.019738391, -0.061790336, -0.00026213622)
            point3f physics:localPos1 = (0, 0, 0)
            quatf physics:localRot0 = (0.71131164, 0, -0.0070747924, 0.70284116)
            quatf physics:localRot1 = (0.71131164, 0, -0.0070747924, 0.70284116)
            float physics:lowerLimit = -160.00018
            float physics:upperLimit = 160.00018
            custom float urdf:limit:effort = 30
            custom float urdf:limit:velocity = 3
        }

        def PhysicsRevoluteJoint "left_joint6" (
            prepend apiSchemas = ["PhysicsDriveAPI:angular", "PhysicsJointStateAPI:angular"]
        )
        {
            float drive:angular:physics:maxForce = 30
            uniform token physics:axis = "X"
            custom rel physics:body0
            prepend rel physics:body0 = </Aloha/Geometry/base_link/vertical_link/left_link1/left_link2/left_link3/left_link4/left_link5>
            custom rel physics:body1
            prepend rel physics:body1 = </Aloha/Geometry/base_link/vertical_link/left_link1/left_link2/left_link3/left_link4/left_link5/left_link6>
            point3f physics:localPos0 = (0.018772023, -0.023828154, 0.020003509)
            point3f physics:localPos1 = (0, 0, 0)
            quatf physics:localRot0 = (0.007425247, 0, 0.5875591, 0.80914724)
            quatf physics:localRot1 = (0.007425247, 0, 0.5875591, 0.80914724)
            float physics:lowerLimit = -105.99719
            float physics:upperLimit = 100.000046
            custom float urdf:limit:effort = 30
            custom float urdf:limit:velocity = 3
        }

        def PhysicsRevoluteJoint "right_joint1" (
            prepend apiSchemas = ["PhysicsDriveAPI:angular", "PhysicsJointStateAPI:angular"]
        )
        {
            float drive:angular:physics:maxForce = 30
            uniform token physics:axis = "X"
            custom rel physics:body0
            prepend rel physics:body0 = </Aloha/Geometry/base_link/vertical_link>
            custom rel physics:body1
            prepend rel physics:body1 = </Aloha/Geometry/base_link/vertical_link/right_link1>
            point3f physics:localPos0 = (-0.15721878, -0.015354435, 0.75423735)
            point3f physics:localPos1 = (0, 0, 0)
            quatf physics:localRot0 = (0.70714885, 0, 0.7070294, 0.007062097)
            quatf physics:localRot1 = (0.70714885, 0, 0.7070294, 0.007062097)
            float physics:lowerLimit = -109.99988
            float physics:upperLimit = 109.99988
            custom float urdf:limit:effort = 30
            custom float urdf:limit:velocity = 3
        }

        def PhysicsRevoluteJoint "right_joint2" (
            prepend apiSchemas = ["PhysicsDriveAPI:angular", "PhysicsJointStateAPI:angular"]
        )
        {
            float drive:angular:physics:maxForce = 30
            uniform token physics:axis = "X"
            custom rel physics:body0
            prepend rel physics:body0 = </Aloha/Geometry/base_link/vertical_link/right_link1>
            custom rel physics:body1
            prepend rel physics:body1 = </Aloha/Geometry/base_link/vertical_link/right_link1/right_link2>
            point3f physics:localPos0 = (-0.01727994, -0.0311811, 0.053936154)
            point3f physics:localPos1 = (0, 0, 0)
            quatf physics:localRot0 = (0.9999987, 0, -0.000043497945, -0.0016003461)
            quatf physics:localRot1 = (0.9999987, 0, -0.000043497945, -0.0016003461)
            float physics:lowerLimit = -100.000046
            float physics:upperLimit = 100.000046
            custom float urdf:limit:effort = 30
            custom float urdf:limit:velocity = 3
        }

        def PhysicsRevoluteJoint "right_joint3" (
            prepend apiSchemas = ["PhysicsDriveAPI:angular", "PhysicsJointStateAPI:angular"]
        )
        {
            float drive:angular:physics:maxForce = 30
            uniform token physics:axis = "X"
            custom rel physics:body0
            prepend rel physics:body0 = </Aloha/Geometry/base_link/vertical_link/right_link1/right_link2>
            custom rel physics:body1
            prepend rel physics:body1 = </Aloha/Geometry/base_link/vertical_link/right_link1/right_link2/right_link3>
            point3f physics:localPos0 = (0.0028522825, 0.11237908, 0.02882863)
            point3f physics:localPos1 = (0, 0, 0)
            quatf physics:localRot0 = (0.9999889, 0, -0.004405384, -0.0016449662)
            quatf physics:localRot1 = (0.9999889, 0, -0.004405384, -0.0016449662)
            float physics:lowerLimit = -100.000046
            float physics:upperLimit = 90.00021
            custom float urdf:limit:effort = 30
            custom float urdf:limit:velocity = 3
        }

        def PhysicsRevoluteJoint "right_joint4" (
            prepend apiSchemas = ["PhysicsDriveAPI:angular", "PhysicsJointStateAPI:angular"]
        )
        {
            float drive:angular:physics:maxForce = 30
            uniform token physics:axis = "X"
            custom rel physics:body0
            prepend rel physics:body0 = </Aloha/Geometry/base_link/vertical_link/right_link1/right_link2/right_link3>
            custom rel physics:body1
            prepend rel physics:body1 = </Aloha/Geometry/base_link/vertical_link/right_link1/right_link2/right_link3/right_link4>
            point3f physics:localPos0 = (0.0004820973, -0.13414858, 0.0036238108)
            point3f physics:localPos1 = (0, 0, 0)
            quatf physics:localRot0 = (0.9999436, 0, -0.008725049, -0.0060510905)
            quatf physics:localRot1 = (0.9999436, 0, -0.008725049, -0.0060510905)
            float physics:lowerLimit = -94.99984
            float physics:upperLimit = 94.99984
            custom float urdf:limit:effort = 30
            custom float urdf:limit:velocity = 3
        }

        def PhysicsRevoluteJoint "right_joint5" (
            prepend apiSchemas = ["PhysicsDriveAPI:angular", "PhysicsJointStateAPI:angular"]
        )
        {
            float drive:angular:physics:maxForce = 30
            uniform token physics:axis = "X"
            custom rel physics:body0
            prepend rel physics:body0 = </Aloha/Geometry/base_link/vertical_link/right_link1/right_link2/right_link3/right_link4>
            custom rel physics:body1
            prepend rel physics:body1 = </Aloha/Geometry/base_link/vertical_link/right_link1/right_link2/right_link3/right_link4/right_link5>
            point3f physics:localPos0 = (0.019738391, -0.061790336, -0.00026213622)
            point3f physics:localPos1 = (0, 0, 0)
            quatf physics:localRot0 = (0.71131164, 0, -0.0070747924, 0.70284116)
            quatf physics:localRot1 = (0.71131164, 0, -0.0070747924, 0.70284116)
            float physics:lowerLimit = -160.00018
            float physics:upperLimit = 160.00018
            custom float urdf:limit:effort = 30
            custom float urdf:limit:velocity = 3
        }

        def PhysicsRevoluteJoint "right_joint6" (
            prepend apiSchemas = ["PhysicsDriveAPI:angular", "PhysicsJointStateAPI:angular"]
        )
        {
            float drive:angular:physics:maxForce = 30
            uniform token physics:axis = "X"
            custom rel physics:body0
            prepend rel physics:body0 = </Aloha/Geometry/base_link/vertical_link/right_link1/right_link2/right_link3/right_link4/right_link5>
            custom rel physics:body1
            prepend rel physics:body1 = </Aloha/Geometry/base_link/vertical_link/right_link1/right_link2/right_link3/right_link4/right_link5/right_link6>
            point3f physics:localPos0 = (0.018772023, -0.023828154, 0.020003509)
            point3f physics:localPos1 = (0, 0, 0)
            quatf physics:localRot0 = (0.007425247, 0, 0.5875591, 0.80914724)
            quatf physics:localRot1 = (0.007425247, 0, 0.5875591, 0.80914724)
            float physics:lowerLimit = -105.99719
            float physics:upperLimit = 100.000046
            custom float urdf:limit:effort = 30
            custom float urdf:limit:velocity = 3
        }
    }
}

